Workbook
Name bex: OFFSET('[1]Trend-Table'!$A$5,0,5,'[1]Trend-Table'!$B$1,1)
Name bgreen: OFFSET('[1]Trend-Table'!$A$5,0,4,'[1]Trend-Table'!$B$1,1)
Name borange: OFFSET('[1]Trend-Table'!$A$5,0,2,'[1]Trend-Table'!$B$1,1)
Name boverall: OFFSET('[1]Trend-Table'!$A$5,0,25,'[1]Trend-Table'!$B$1,1)
Name bred: OFFSET('[1]Trend-Table'!$A$5,0,1,'[1]Trend-Table'!$B$1,1)
Name byellow: OFFSET('[1]Trend-Table'!$A$5,0,3,'[1]Trend-Table'!$B$1,1)
Name dates: OFFSET('[1]Trend-Table'!$A$5,0,0,'[1]Trend-Table'!$B$1,1)

Sheet VLOOKUP
A1: Enter barcode
A2: Barcode | B2: Article
B3: =IFERROR(VLOOKUP(A3,'ZDET-PRICE'!Z:AE,6,0),"")
B4: =IFERROR(VLOOKUP(A4,'ZDET-PRICE'!Z:AE,6,0),"")
B5: =IFERROR(VLOOKUP(A5,'ZDET-PRICE'!Z:AE,6,0),"")
B6: =IFERROR(VLOOKUP(A6,'ZDET-PRICE'!Z:AE,6,0),"")
B7: =IFERROR(VLOOKUP(A7,'ZDET-PRICE'!Z:AE,6,0),"")
B8: =IFERROR(VLOOKUP(A8,'ZDET-PRICE'!Z:AE,6,0),"")
B9: =IFERROR(VLOOKUP(A9,'ZDET-PRICE'!Z:AE,6,0),"")
B10: =IFERROR(VLOOKUP(A10,'ZDET-PRICE'!Z:AE,6,0),"")
B11: =IFERROR(VLOOKUP(A11,'ZDET-PRICE'!Z:AE,6,0),"")
B12: =IFERROR(VLOOKUP(A12,'ZDET-PRICE'!Z:AE,6,0),"")
B13: =IFERROR(VLOOKUP(A13,'ZDET-PRICE'!Z:AE,6,0),"")
B14: =IFERROR(VLOOKUP(A14,'ZDET-PRICE'!Z:AE,6,0),"")
... B38: =IFERROR(VLOOKUP(A38,'ZDET-PRICE'!Z:AE,6,0),"")
A39: 24000104582 | B39: =IFERROR(VLOOKUP(A39,'ZDET-PRICE'!Z:AE,6,0),"") -> 91599 | C39: 9566686862
A40: 8720865190587 | B40: =IFERROR(VLOOKUP(A40,'ZDET-PRICE'!Z:AE,6,0),"") -> 372605
A41: 24000238171 | B41: =IFERROR(VLOOKUP(A41,'ZDET-PRICE'!Z:AE,6,0),"") -> 165099
A42: 24000025528 | B42: =IFERROR(VLOOKUP(A42,'ZDET-PRICE'!Z:AE,6,0),"") -> 91552
A43: 24000025993 | B43: =IFERROR(VLOOKUP(A43,'ZDET-PRICE'!Z:AE,6,0),"") -> 91555
A44: 6291106770421 | B44: =IFERROR(VLOOKUP(A44,'ZDET-PRICE'!Z:AE,6,0),"")
A45: 1800000016020 | B45: =IFERROR(VLOOKUP(A45,'ZDET-PRICE'!Z:AE,6,0),"") -> 356748
A46: 6291106770322 | B46: =IFERROR(VLOOKUP(A46,'ZDET-PRICE'!Z:AE,6,0),"") | C46: 12
A47: 8682790000419 | B47: =IFERROR(VLOOKUP(A47,'ZDET-PRICE'!Z:AE,6,0),"") -> 412004 | C47: 12
A48: 6921211117094 | B48: =IFERROR(VLOOKUP(A48,'ZDET-PRICE'!Z:AE,6,0),"") -> 371251 | C48: 12
A49: 8935001725572 | B49: =IFERROR(VLOOKUP(A49,'ZDET-PRICE'!Z:AE,6,0),"") -> 327491 | C49: 24
A50: 8935001729570 | B50: =IFERROR(VLOOKUP(A50,'ZDET-PRICE'!Z:AE,6,0),"") -> 412010 | C50: 24
A51: 8935001727309 | B51: =IFERROR(VLOOKUP(A51,'ZDET-PRICE'!Z:AE,6,0),"") -> 384691 | C51: 24
A52: 8935001729068 | B52: =IFERROR(VLOOKUP(A52,'ZDET-PRICE'!Z:AE,6,0),"") -> 412009 | C52: 24
A53: 8935001727293 | B53: =IFERROR(VLOOKUP(A53,'ZDET-PRICE'!Z:AE,6,0),"") -> 384692 | C53: 12
A54: 8990800007793 | B54: =IFERROR(VLOOKUP(A54,'ZDET-PRICE'!Z:AE,6,0),"") -> 176176 | C54: 6 | E54: =283001-43680-5448 -> 233873
A55: 6291106770421 | B55: =IFERROR(VLOOKUP(A55,'ZDET-PRICE'!Z:AE,6,0),"") | C55: 24
A56: 8935001726289 | B56: =IFERROR(VLOOKUP(A56,'ZDET-PRICE'!Z:AE,6,0),"") -> 378596
A57: 80756590 | B57: =IFERROR(VLOOKUP(A57,'ZDET-PRICE'!Z:AE,6,0),"") -> 138940
A58: 8935001724513 | B58: =IFERROR(VLOOKUP(A58,'ZDET-PRICE'!Z:AE,6,0),"") -> 271359
A59: 6921211117025 | B59: =IFERROR(VLOOKUP(A59,'ZDET-PRICE'!Z:AE,6,0),"") -> 365133
A60: 8935001722533 | B60: =IFERROR(VLOOKUP(A60,'ZDET-PRICE'!Z:AE,6,0),"") -> 184051
A61: 8935001722519 | B61: =IFERROR(VLOOKUP(A61,'ZDET-PRICE'!Z:AE,6,0),"") -> 183930
A62: 84196033 | B62: =IFERROR(VLOOKUP(A62,'ZDET-PRICE'!Z:AE,6,0),"") -> 176191
A63: 84155634 | B63: =IFERROR(VLOOKUP(A63,'ZDET-PRICE'!Z:AE,6,0),"") -> 176188
...

Sheet ZDET-PRICE
A1: 1 | B1: =A1+1 -> 2 | C1: =B1+1 -> 3 | D1: =C1+1 -> 4 | E1: =D1+1 -> 5 | F1: =E1+1 -> 6 | G1: =F1+1 -> 7 | H1: =G1+1 -> 8 | I1: =H1+1 -> 9 | ... AD1: =AC1+1 -> 30 | AE1: 1
A2: Article | B2: Material Description | C2: Brand Name | D2: Site-sp.artl status | E2: Old article number | F2: Type (R/P/F/P1) | G2: Vendor Article Number | H2: Base Unit of Measure | I2: Alternative UoM 1 | J2: Den. for Conversion 1 | K2: Alternative UoM 2 | L2: Den. for Conversion 2 | M2: Alternative UoM 3 | N2: Den. for Conversion 3 | O2: Alternative UoM 4 | P2: Den. for Conversion 4 | Q2: Gross Weight | R2: Net Weight | S2: Weight Unit | T2: Length | U2: Width | V2: Height | W2: Net price-Base UoM (Landed Cost) | X2: Selling Price- Base UoM (1st Slab) | Y2: SUF per Article | Z2: GTIN | AA2: Total shelf life | AB2: Min. Rem. Shelf Life | AC2: Vendor Name | AD2: Cs | AE2: Article
A3: 91275 | B3: PONS(12)EV OIL 500ML | C3: PONS | E3: 16/43/02 | F3: R | H3: BT | I3: BT | J3: 1 | K3: EA | L3: 1 | M3: CAR | N3: 12 | P3: 0 | Q3: 0.865 | R3: 0.458 | S3: KG | T3: 2.208 | U3: 1.125 | V3: 2.25 | W3: 1.659 | X3: 2.385 | Y3: 0 | Z3: 8429671350061 | AA3: 729 | AB3: 60 | AD3: 12 | AE3: =A3 -> 91275
A4: 91277 | B4: PONS(6)EV OIL 1LTR | C4: PONS | E4: 16/43/03 | F4: R | H4: BT | I4: BT | J4: 1 | K4: EA | L4: 1 | M4: CAR | N4: 6 | P4: 0 | Q4: 1.6 | R4: 0.916 | S4: KG | T4: 8 | U4: 8 | V4: 30 | W4: 3.183 | X4: 4.683 | Y4: 0 | Z4: 8429671350115 | AA4: 729 | AB4: 60 | AD4: 6 | AE4: =A4 -> 91277
A5: 91284 | B5: PONS(12)PURE OLIVE OIL 500ML | C5: PONS | E5: 16/43/12 | F5: R | H5: BT | I5: BT | J5: 1 | K5: EA | L5: 1 | M5: CAR | N5: 12 | P5: 0 | Q5: 0.865 | R5: 0.458 | S5: KG | T5: 6.4 | U5: 6.4 | V5: 26 | W5: 1.564 | X5: 2.212 | Y5: 0 | Z5: 8429671350092 | AA5: 729 | AB5: 60 | AD5: 12 | AE5: =A5 -> 91284
A6: 91531 | B6: DM(24) FRUIT COCKTAIL 420GM | C6: DELMONTE | E6: 16/70/01 | F6: R | H6: CAN | I6: EA | J6: 1 | K6: CAN | L6: 1 | M6: CAR | N6: 24 | P6: 0 | Q6: 0.5 | R6: 0.42 | S6: KG | T6: 7.5 | U6: 7.5 | V6: 11 | W6: 0.463 | X6: 0.574 | Y6: 0 | Z6: 24000024675 | AA6: 729 | AB6: 90 | AC6: DEL MONTE FOODS (U.A.E) FZE | AD6: 24 | AE6: =A6 -> 91531
A7: 91535 | B7: DM(24) FRUIT COCKTAIL 825GM | C7: DELMONTE | E7: 16/70/02 | F7: R | H7: CAN | I7: EA | J7: 1 | K7: CAN | L7: 1 | M7: CAR | N7: 24 | P7: 0 | Q7: 0.925 | R7: 0.825 | S7: KG | T7: 10 | U7: 10 | V7: 12 | W7: 0.777 | X7: 0.921 | Y7: 0 | Z7: 24000010920 | AA7: 729 | AB7: 90 | AC7: DEL MONTE FOODS (U.A.E) FZE | AD7: 24 | AE7: =A7 -> 91535
A8: 91538 | B8: DM(24) FRUIT COCKTAIL 227GM | C8: DELMONTE | E8: 16/70/03 | F8: R | H8: CAN | I8: EA | J8: 1 | K8: CAN | L8: 1 | M8: CAR | N8: 24 | P8: 0 | Q8: 0.25 | R8: 0.227 | S8: KG | T8: 7 | U8: 7 | V8: 8 | W8: 0.374 | X8: 0.465 | Y8: 0 | Z8: 24000011477 | AA8: 729 | AB8: 90 | AC8: DEL MONTE FOODS (U.A.E) FZE | AD8: 24 | AE8: =A8 -> 91538
A9: 91552 | B9: DM(24) PEACH HALVES 420GM | C9: DELMONTE | E9: 16/70/11 | F9: R | H9: CAN | I9: EA | J9: 1 | K9: CAN | L9: 1 | M9: CAR | N9: 24 | P9: 0 | Q9: 0.5 | R9: 0.42 | S9: KG | T9: 7.5 | U9: 7.5 | V9: 11 | W9: 0.412 | X9: 0.498 | Y9: 0 | Z9: 24000025528 | AA9: 729 | AB9: 90 | AC9: DEL MONTE FOODS (U.A.E) FZE | AD9: 24 | AE9: =A9 -> 91552
A10: 91554 | B10: DM(24) PEACH HALVES 825GM | C10: DELMONTE | E10: 16/70/12 | F10: R | H10: CAN | I10: EA | J10: 1 | K10: CAN | L10: 1 | M10: CAR | N10: 24 | P10: 0 | Q10: 0.925 | R10: 0.825 | S10: KG | T10: 10 | U10: 10 | V10: 12 | W10: 0.726 | X10: 0.829 | Y10: 0 | Z10: 24000010418 | AA10: 729 | AB10: 90 | AC10: DEL MONTE FOODS (U.A.E) FZE | AD10: 24 | AE10: =A10 -> 91554
A11: 91555 | B11: DM(24) PEACH SLICES 420GM | C11: DELMONTE | E11: 16/70/13 | F11: R | H11: CAN | I11: EA | J11: 1 | K11: CAN | L11: 1 | M11: CAR | N11: 24 | P11: 0 | Q11: 0.5 | R11: 0.42 | S11: KG | T11: 7.5 | U11: 7.5 | V11: 11 | W11: 0.412 | X11: 0.474 | Y11: 0 | Z11: 24000025993 | AA11: 729 | AB11: 90 | AC11: DEL MONTE FOODS (U.A.E) FZE | AD11: 24 | AE11: =A11 -> 91555
A12: 91558 | B12: DM(48) PINEAPPLE SLICES 235GM | C12: DELMONTE | E12: 16/70/19 | F12: R | H12: CAN | I12: EA | J12: 1 | K12: CAN | L12: 1 | M12: CAR | N12: 48 | P12: 0 | Q12: 0.3 | R12: 0.234 | S12: KG | T12: 8.5 | U12: 8.5 | V12: 5 | W12: 0.233 | X12: 0.305 | Y12: 0 | Z12: 24000003649 | AA12: 729 | AB12: 90 | AC12: DEL MONTE FOODS (U.A.E) FZE | AD12: 48 | AE12: =A12 -> 91558
A13: 91560 | B13: DM(24) PINEAPPLE SLICES 432GM | C13: DELMONTE | E13: 16/70/20 | F13: R | H13: CAN | I13: EA | J13: 1 | K13: CAN | L13: 1 | M13: CAR | N13: 24 | P13: 0 | Q13: 0.52 | R13: 0.432 | S13: KG | T13: 8.5 | U13: 8.5 | V13: 9 | W13: 0.415 | X13: 0.54 | Y13: 0 | Z13: 24000015963 | AA13: 729 | AB13: 90 | AC13: DEL MONTE FOODS (U.A.E) FZE | AD13: 24 | AE13: =A13 -> 91560
A14: 91566 | B14: DM(24) PINEAPPLE SLICES 567GM | C14: DELMONTE | E14: 16/70/21 | F14: R | H14: CAN | I14: EA | J14: 1 | K14: CAN | L14: 1 | M14: CAR | N14: 24 | P14: 0 | Q14: 0.28 | R14: 0.567 | S14: KG | T14: 8.5 | U14: 8.5 | V14: 11.5 | W14: 0.482 | X14: 0.601 | Y14: 0 | Z14: 24000012313 | AA14: 729 | AB14: 90 | AC14: DEL MONTE FOODS (U.A.E) FZE | AD14: 24 | AE14: =A14 -> 91566
A15: 91570 | B15: DM(48) PINEAPPLE CHUNK 234GM | C15: DELMONTE | E15: 16/70/24 | F15: R | H15: CAN | I15: EA | J15: 1 | K15: CAN | L15: 1 | M15: CAR | N15: 48 | P15: 0 | Q15: 0.28 | R15: 0.234 | S15: KG | T15: 8.5 | U15: 8.5 | V15: 5 | W15: 0.236 | X15: 0.305 | Y15: 0 | Z15: 24000008934 | AA15: 729 | AB15: 90 | AC15: DEL MONTE FOODS (U.A.E) FZE | AD15: 48 | AE15: =A15 -> 91570
A16: 91572 | B16: DM(24) PINEAPPLE CHUNK 435GM | C16: DELMONTE | E16: 16/70/25 | F16: R | H16: CAN | I16: EA | J16: 1 | K16: CAN | L16: 1 | M16: CAR | N16: 24 | P16: 0 | Q16: 0.52 | R16: 0.432 | S16: KG | T16: 8.5 | U16: 85 | V16: 9 | W16: 0.418 | X16: 0.555 | Y16: 0 | Z16: 24000015970 | AA16: 729 | AB16: 90 | AC16: DEL MONTE FOODS (U.A.E) FZE | AD16: 24 | AE16: =A16 -> 91572
A17: 91575 | B17: DM(24) PINEAPPLE CHUNK 570GM | C17: DELMONTE | E17: 16/70/27 | F17: R | H17: CAN | I17: EA | J17: 1 | K17: CAN | L17: 1 | M17: CAR | N17: 24 | P17: 0 | Q17: 0.66 | R17: 0.567 | S17: KG | T17: 8.5 | U17: 8.5 | V17: 11.5 | W17: 0.474 | X17: 0.586 | Y17: 0 | Z17: 24000012412 | AA17: 729 | AB17: 90 | AC17: DEL MONTE FOODS (U.A.E) FZE | AD17: 24 | AE17: =A17 -> 91575
... A25: 91614 | B25: DM JUICE PINEAPPLE-UNSWEETED 6X240ML | C25: DELMONTE | E25: 16/70/89ASPR6 | F25: P | H25: SET | I25: EA | J25: 1 | K25: CAR | L25: 4 | M25: SET | N25: 1 | P25: 0 | Q25: 1.8 | R25: 0 | S25: KG | T25: 15 | U25: 10 | V25: 13 | W25: 0.841 | X25: 1.055 | Y25: 0 | Z25: 6291106770223 | AA25: 729 | AB25: 60 | AC25: KR COMMODITY DIVN. | AD25: 4 | AE25: =A25 -> 91614
A26: 94567 | B26: REGAL PICON 72PORTION 1080G | C26: REGAL PICON | D26: K6 | E26: 18/1/011080 | F26: R | H26: EA | I26: EA | J26: 1 | K26: CAR | L26: 8 | M26: KG | N26: 25 | O26: TO | P26: 25000 | Q26: 1.08 | R26: 1.08 | S26: KG | T26: 4.4 | U26: 4.4 | V26: 6.1 | W26: 2.23 | X26: 2.703 | Y26: 0 | Z26: 3073780884655 | AA26: 288 | AB26: 60 | AC26: BEL MIDDLE EAST GENERAL TRADING L.L | AD26: 8 | AE26: =A26 -> 94567
A27: 94576 | B27: REGAL PICON 16PORTION 240G | C27: REGAL PICON | D27: K6 | E27: 18/1/01240 | F27: R | H27: EA | I27: EA | J27: 1 | K27: CAR | L27: 32 | M27: KG | N27: 1000 | O27: TO | P27: 12500 | Q27: 0.24 | R27: 0.24 | S27: KG | T27: 4.4 | U27: 4.4 | V27: 1.4 | W27: 0.676 | X27: 0.819 | Y27: 0 | Z27: 3251350161003 | AA27: 288 | AB27: 60 | AC27: BEL MIDDLE EAST GENERAL TRADING L.L | AD27: 32 | AE27: =A27 -> 94576
A28: 94581 | B28: REGAL PICON 24PORTION 360G | C28: REGAL PICON | D28: K6 | E28: 18/1/01360 | F28: R | H28: EA | I28: EA | J28: 1 | K28: CAR | L28: 24 | M28: KG | N28: 1000 | O28: TO | P28: 25000 | Q28: 0.36 | R28: 0.32 | S28: KG | T28: 4.4 | U28: 4.4 | V28: 1.9 | W28: 1.01 | X28: 1.225 | Y28: 0 | Z28: 3251350162000 | AA28: 288 | AB28: 60 | AC28: BEL MIDDLE EAST GENERAL TRADING L.L | AD28: 24 | AE28: =A28 -> 94581
A29: 94590 | B29: REGAL PICON 32PORTION 480G | C29: REGAL PICON | D29: K6 | E29: 18/1/01480 | F29: R | H29: EA | I29: EA | J29: 1 | K29: CAR | L29: 16 | M29: KG | N29: 1000 | O29: TO | P29: 6250 | Q29: 0.48 | R29: 0.48 | S29: KG | T29: 4.4 | U29: 4.4 | V29: 2.5 | W29: 1.313 | X29: 1.592 | Y29: 0 | Z29: 3251350163007 | AA29: 288 | AB29: 60 | AC29: BEL MIDDLE EAST GENERAL TRADING L.L | AD29: 16 | AE29: =A29 -> 94590
A30: 94595 | B30: REGAL PICON 32PORTION 2X480G PB | C30: REGAL PICON | D30: K6 | E30: 18/1/01480X2/CTN | F30: P1 | H30: SET | I30: EA | J30: 1 | K30: CAR | L30: 8 | M30: KG | N30: 1000 | O30: SET | P30: 1 | Q30: 7.68 | R30: 7.68 | S30: KG | T30: 11.5 | U30: 12.5 | V30: 12.5 | W30: 2.365 | X30: 2.866 | Y30: 0 | Z30: 3073781053616 | AA30: 288 | AB30: 60 | AC30: BEL MIDDLE EAST GENERAL TRADING L.L | AD30: 8 | AE30: =A30 -> 94595
A31: 94649 | B31: LES ENFANTS 24PORTION 360G | C31: LES ENFANTS | D31: K6 | E31: 18/1/02360 | F31: R | H31: EA | I31: EA | J31: 1 | K31: CAR | L31: 24 | M31: KG | N31: 1000 | O31: TO | P31: 25000 | Q31: 0.36 | R31: 0.36 | S31: KG | T31: 4.4 | U31: 4.4 | V31: 1.9 | W31: 1.01 | X31: 1.225 | Y31: 0 | Z31: 3073780905831 | AA31: 293 | AB31: 60 | AC31: BEL MIDDLE EAST GENERAL TRADING L.L | AD31: 24 | AE31: =A31 -> 94649
A32: 94659 | B32: LA VACHE QUIRIT 16PORTION 240G | C32: LA VACHE QUIRIT | D32: K6 | E32: 18/1/03240 | F32: R | H32: EA | I32: EA | J32: 1 | K32: CAR | L32: 32 | M32: KG | N32: 1000 | O32: TO | P32: 12500 | Q32: 0.26 | R32: 0.24 | S32: KG | T32: 11.5 | U32: 11.5 | V32: 3.5 | W32: 0.806 | X32: 0.977 | Y32: 0 | Z32: 3073780574242 | AA32: 288 | AB32: 60 | AC32: BEL MIDDLE EAST GENERAL TRADING L.L | AD32: 32 | AE32: =A32 -> 94659
A33: 94661 | B33: LA VACHE QUIRIT 24PORTION 360G | C33: LA VACHE QUIRIT | D33: K6 | E33: 18/1/03360 | F33: R | H33: EA | I33: EA | J33: 1 | K33: CAR | L33: 24 | M33: KG | N33: 1000 | O33: TO | P33: 25000 | Q33: 0.36 | R33: 0.36 | S33: KG | T33: 4.4 | U33: 4.4 | V33: 1.9 | W33: 1.178 | X33: 1.428 | Y33: 0 | Z33: 3073780574310 | AA33: 288 | AB33: 60 | AC33: BEL MIDDLE EAST GENERAL TRADING L.L | AD33: 24 | AE33: =A33 -> 94661
A34: 94664 | B34: LA VACHE QUIRIT 32PORTION 480G | C34: LA VACHE QUIRIT | D34: K6 | E34: 18/1/03480 | F34: R | H34: EA | I34: EA | J34: 1 | K34: CAR | L34: 16 | M34: KG | N34: 1000 | O34: TO | P34: 6250 | Q34: 0.48 | R34: 0.48 | S34: KG | T34: 4.4 | U34: 4.4 | V34: 2.5 | W34: 1.549 | X34: 1.878 | Y34: 0 | Z34: 3073780593083 | AA34: 288 | AB34: 60 | AC34: BEL MIDDLE EAST GENERAL TRADING L.L | AD34: 16 | AE34: =A34 -> 94664
A35: 94671 | B35: LA VACHE QUIRIT SLICES CHEDDAR 200G | C35: LA VACHE QUIRIT | D35: K6 | E35: 18/1/03CHD200 | F35: R | H35: EA | I35: EA | J35: 1 | K35: CAR | L35: 32 | M35: KG | N35: 1000 | O35: TO | P35: 5000 | Q35: 0.213 | R35: 0.2 | S35: KG | T35: 11.5 | U35: 11.5 | V35: 3.5 | W35: 0.705 | X35: 0.853 | Y35: 0 | Z35: 3073780450461 | AA35: 274 | AB35: 60 | AC35: BEL MIDDLE EAST GENERAL TRADING L.L | AD35: 32 | AE35: =A35 -> 94671
A36: 94672 | B36: LA VACHE QUIRIT SLICES CHEDDAR 480G | C36: LA VACHE QUIRIT | D36: K6 | E36: 18/1/03CHD480 | F36: R | H36: EA | I36: EA | J36: 1 | K36: CAR | L36: 12 | M36: KG | N36: 1000 | O36: TO | P36: 6250 | Q36: 0.517 | R36: 0.48 | S36: KG | T36: 17 | U36: 8 | V36: 4 | W36: 1.561 | X36: 1.893 | Y36: 0 | Z36: 3073780985604 | AA36: 274 | AB36: 60 | AC36: BEL MIDDLE EAST GENERAL TRADING L.L | AD36: 12 | AE36: =A36 -> 94672
A37: 94674 | B37: LA VACHE QUIRIT SLICES BURGER 200G | C37: LA VACHE QUIRIT | D37: K6 | E37: 18/1/03HAM200 | F37: R | H37: EA | I37: EA | J37: 1 | K37: CAR | L37: 32 | M37: KG | N37: 1000 | O37: TO | P37: 5000 | Q37: 0.213 | R37: 0.2 | S37: KG | T37: 8.5 | U37: 8.5 | V37: 3 | W37: 0.705 | X37: 0.853 | Y37: 0 | Z37: 3073780985581 | AA37: 274 | AB37: 60 | AC37: BEL MIDDLE EAST GENERAL TRADING L.L | AD37: 32 | AE37: =A37 -> 94674
... A44: 94734 | B44: BABYBEL MINI LIGHT 100G | C44: BABYBEL | D44: K6 | E44: 18/1/05BL100 | F44: R | H44: EA | I44: EA | J44: 1 | K44: CAR | L44: 12 | M44: KG | N44: 1000 | O44: TO | P44: 10000 | Q44: 0.26 | R44: 0.1 | S44: KG | T44: 11.5 | U44: 11.5 | V44: 3.5 | W44: 1.104 | X44: 1.337 | Y44: 0 | Z44: 3073780574242 | AA44: 174 | AB44: 30 | AC44: BEL MIDDLE EAST GENERAL TRADING L.L | AD44: 12 | AE44: =A44 -> 94734
A45: 106958 | B45: PONS(12)EV OIL 250ML | C45: PONS | F45: R | H45: EA | I45: EA | J45: 1 | K45: CAR | L45: 12 | N45: 0 | P45: 0 | Q45: 0.48 | R45: 0.223 | S45: KG | T45: 5 | U45: 5 | V45: 22 | W45: 0.968 | X45: 1.275 | Y45: 0 | Z45: 8429671350054 | AA45: 729 | AB45: 60 | AD45: 12 | AE45: =A45 -> 106958
A46: 106959 | B46: PONS(12)PURE OLIVE OIL 250ML | C46: PONS | F46: R | H46: EA | I46: EA | J46: 1 | K46: CAR | L46: 12 | N46: 0 | P46: 0 | Q46: 0.502 | R46: 0.223 | S46: KG | T46: 5.2 | U46: 5.2 | V46: 21.5 | W46: 0.936 | X46: 1.287 | Y46: 0 | Z46: 8429671350085 | AA46: 729 | AB46: 60 | AD46: 12 | AE46: =A46 -> 106959
A47: 114598 | B47: REGAL PICON SLICE CHEDDAR 12S 200G | C47: REGAL PICON | D47: K6 | F47: R | H47: EA | I47: EA | J47: 1 | K47: CAR | L47: 24 | M47: KG | N47: 5 | O47: TO | P47: 5000 | Q47: 0.2 | R47: 0.2 | S47: KG | T47: 3.4 | U47: 3.4 | V47: 1.1 | W47: 0.717 | X47: 0.869 | Y47: 0 | Z47: 3073780998338 | AA47: 274 | AB47: 60 | AC47: BEL MIDDLE EAST GENERAL TRADING L.L | AD47: 24 | AE47: =A47 -> 114598
A48: 114599 | B48: REGAL PICON SLICE BURGER 12S 200G | C48: REGAL PICON | D48: K6 | F48: R | H48: EA | I48: EA | J48: 1 | K48: CAR | L48: 24 | M48: KG | N48: 5 | O48: TO | P48: 5000 | Q48: 0.2 | R48: 0.2 | S48: KG | T48: 3.4 | U48: 3.4 | V48: 1.1 | W48: 0.717 | X48: 0.869 | Y48: 0 | Z48: 3073780998352 | AA48: 274 | AB48: 60 | AC48: BEL MIDDLE EAST GENERAL TRADING L.L | AD48: 24 | AE48: =A48 -> 114599
A49: 114600 | B49: REGAL PICON SLICE CHEDDAR 24S 400G | C49: REGAL PICON | D49: K6 | F49: R | H49: EA | I49: EA | J49: 1 | K49: CAR | L49: 16 | M49: KG | N49: 25 | O49: TO | P49: 2500 | Q49: 0.4 | R49: 0.4 | S49: KG | T49: 6.8 | U49: 3.5 | V49: 1.1 | W49: 1.434 | X49: 1.738 | Y49: 0 | Z49: 3073780998376 | AA49: 274 | AB49: 60 | AC49: BEL MIDDLE EAST GENERAL TRADING L.L | AD49: 16 | AE49: =A49 -> 114600
A50: 133208 | B50: LES ENFANTS 32PORTION 480G | C50: LES ENFANTS | D50: K6 | F50: R | H50: EA | I50: EA | J50: 1 | K50: CAR | L50: 16 | M50: KG | N50: 1000 | O50: TO | P50: 6250 | Q50: 0.48 | R50: 0 | S50: KG | T50: 4.4 | U50: 4.4 | V50: 2.5 | W50: 1.332 | X50: 1.614 | Y50: 0 | Z50: 3073781021226 | AA50: 288 | AB50: 60 | AC50: BEL MIDDLE EAST GENERAL TRADING L.L | AD50: 16 | AE50: =A50 -> 133208
A51: 138937 | B51: MENTOS WHITE BOTTLE SWEETMINT | C51: MENTOS | D51: K6 | F51: R | G51: 856244 | H51: EA | I51: CV | J51: 6 | K51: EA | L51: 1 | M51: CAR | N51: 72 | P51: 0 | Q51: 0.04 | R51: 0.043 | S51: KG | T51: 5 | U51: 5 | V51: 7.5 | W51: 0.467 | X51: 0.631 | Y51: 0 | Z51: 8990800002873 | AA51: 540 | AB51: 30 | AC51: PERFETTI VAN MELLE INDONESIA | AD51: 72 | AE51: =A51 -> 138937
A52: 138938 | B52: MENTOS WHITE BOTTLE TUTTI FRUTTI | C52: MENTOS | D52: K6 | F52: R | G52: 856245 | H52: EA | I52: CV | J52: 6 | K52: EA | L52: 1 | M52: CAR | N52: 72 | P52: 0 | Q52: 0.04 | R52: 0.043 | S52: KG | T52: 2 | U52: 2 | V52: 9 | W52: 0.467 | X52: 0.631 | Y52: 0 | Z52: 8990800002873 | AA52: 540 | AB52: 30 | AC52: PERFETTI VAN MELLE INDONESIA | AD52: 72 | AE52: =A52 -> 138938
A53: 138939 | B53: MENTOS BOTTLE WINTER GREEN | C53: MENTOS | D53: K6 | F53: R | G53: 1508796 | H53: EA | I53: CV | J53: 6 | K53: EA | L53: 1 | M53: CAR | N53: 36 | P53: 0 | Q53: 0.04 | R53: 0.056 | S53: KG | T53: 4 | U53: 3 | V53: 8.5 | W53: 0.657 | X53: 0.889 | Y53: 0 | Z53: 8003440963227 | AA53: 540 | AB53: 60 | AC53: PERFETTI VAN MELLE INDONESIA | AD53: 36 | AE53: =A53 -> 138939
...
