Workbook

Sheet Lulu
A1: LULU CODE | B1: PRODUCT | C1: PACKING | D1: ORDER | E1: BARCODES | F1: KR CODE | G1: REMARKS | H1: NEW PRICE
A2: 100565 | B2: 8 Portions RP | C2: 40x120gm | D2: Ctn | E2: 3251350126002 | F2: 152859 | G2: =IFERROR(VLOOKUP(F2,[1]Lulu!$E:$F,2,0),"") -> 100565 | H2: =IFERROR(G2-A2,"") -> 0
A3: 100567 | B3: 16 Portions | C3: 32x240gm | D3: Ctn | E3: 3073780896504 | F3: 94576 | G3: =IFERROR(VLOOKUP(F3,[1]Lulu!$E:$F,2,0),"") -> 100567 | H3: =IFERROR(G3-A3,"") -> 0
A4: 71252 | B4: 24 Portions | C4: 24x360gm | D4: Ctn | E4: 3073780896528 | F4: 94581 | G4: =IFERROR(VLOOKUP(F4,[1]Lulu!$E:$F,2,0),"") -> 71252 | H4: =IFERROR(G4-A4,"") -> 0
A5: 347068 | B5: 32 Portions | C5: 16x480gm | D5: Ctn | E5: 3073780896542 | F5: 94590 | G5: =IFERROR(VLOOKUP(F5,[1]Lulu!$E:$F,2,0),"") -> 347068 | H5: =IFERROR(G5-A5,"") -> 0
A6: 983035 | B6: 48 Portions | C6: 1x720gm | D6: Pcs | E6: 3073781046601 | F6: 177009 | G6: =IFERROR(VLOOKUP(F6,[1]Lulu!$E:$F,2,0),"") -> 983035 | H6: =IFERROR(G6-A6,"") -> 0
A7: 655536 | B7: R.P Slices Burger | C7: 24x200gm | D7: Ctn | E7: 3073780998352 | F7: 114599 | G7: =IFERROR(VLOOKUP(F7,[1]Lulu!$E:$F,2,0),"") -> 655536 | H7: =IFERROR(G7-A7,"") -> 0
A8: 655534 | B8: R.P Slices Cheddar | C8: 24x200gm | D8: Ctn | E8: 3073780998338 | F8: 114598 | G8: =IFERROR(VLOOKUP(F8,[1]Lulu!$E:$F,2,0),"") -> 655534 | H8: =IFERROR(G8-A8,"") -> 0
A9: 655535 | B9: R.P Slices Family | C9: 16x400gm | D9: Ctn | E9: 3073780998376 | F9: 114600 | G9: =IFERROR(VLOOKUP(F9,[1]Lulu!$E:$F,2,0),"") -> 655535 | H9: =IFERROR(G9-A9,"") -> 0
A10: 657347 | B10: R.P Slice 2x200g - 20% off | D10: Set | E10: 1800000005192 | F10: 122516 | G10: =IFERROR(VLOOKUP(F10,[1]Lulu!$E:$F,2,0),"") -> 657347 | H10: =IFERROR(G10-A10,"") -> 0
A11: 1214623 | B11: R.P.Slice 400gm -20%off | D11: Set | E11: 1800000008148 | G11: =IFERROR(VLOOKUP(F11,[1]Lulu!$E:$F,2,0),"") | H11: =IFERROR(G11-A11,"")
A12: 575539 | B12: Regal Picon White Jar 240G | C12: 24 x 240g | D12: Ctn | E12: 3073781125627 | F12: 293087 | G12: =IFERROR(VLOOKUP(F12,[1]Lulu!$E:$F,2,0),"") -> 575539 | H12: =IFERROR(G12-A12,"") -> 0
A13: 575538 | B13: Regal Picon White Jar 500G | C13: 12 x 500g | D13: Ctn | E13: 3073781125634 | F13: 293088 | G13: =IFERROR(VLOOKUP(F13,[1]Lulu!$E:$F,2,0),"") -> 575538 | H13: =IFERROR(G13-A13,"") -> 0
A14: 1646509 | B14: Regal Picon White Jar 900G | C14: 6 x 900g | D14: Pcs | E14: 3073781125641 | F14: 293293 | G14: =IFERROR(VLOOKUP(F14,[1]Lulu!$E:$F,2,0),"") -> 1646509 | H14: =IFERROR(G14-A14,"") -> 0
A15: 1676485 | B15: Regal Picon White Jar- 3X240G | C15: 8x3x240g | D15: Set | E15: 3073781136982 | F15: 313207 | G15: =IFERROR(VLOOKUP(F15,[1]Lulu!$E:$F,2,0),"") -> 1676485 | H15: =IFERROR(G15-A15,"") -> 0
A16: 586001 | B16: Regal Picon White Jar 2x500Gpromo | C16: 6x2x500g | D16: Set | E16: 3073781134537 | F16: 293294 | G16: =IFERROR(VLOOKUP(F16,[1]Lulu!$E:$F,2,0),"") -> 586001 | H16: =IFERROR(G16-A16,"") -> 0
A17: 1657510 | B17: Regal Picon White Jar 2x900Gpromo | C17: 3x2x900g | D17: Set | E17: 3073781134193 | F17: 293732 | G17: =IFERROR(VLOOKUP(F17,[1]Lulu!$E:$F,2,0),"") -> 1657510 | H17: =IFERROR(G17-A17,"") -> 0
A18: 257160 | B18: Picon Portion Promo | C18: 2x480gm | D18: Set | E18: 3073781053616 | F18: 94595 | G18: =IFERROR(VLOOKUP(F18,[1]Lulu!$E:$F,2,0),"") -> 257160 | H18: =IFERROR(G18-A18,"") -> 0
A19: 590615 | B19: Picon Portion Promo | C19: 5x120gm | D19: Set | E19: 3073781059793 | F19: 155145 | G19: =IFERROR(VLOOKUP(F19,[1]Lulu!$E:$F,2,0),"") -> 590615 | H19: =IFERROR(G19-A19,"") -> 0
A20: 401846 | B20: Picon Portion Promo | C20: 3X360gm | D20: Set | E20: 3073780992114 | F20: 94589 | G20: =IFERROR(VLOOKUP(F20,[1]Lulu!$E:$F,2,0),"") -> 401846 | H20: =IFERROR(G20-A20,"") -> 0
A21: 537522 | B21: Picon 4x8p Ro-1 | C21: 4x8x480gm | D21: Set | E21: 3073780977869 | F21: 395985 | G21: =IFERROR(VLOOKUP(H21,[1]Lulu!$E:$F,2,0),"") -> 537522 | H21: 252498 | I21: CODE OLD
A22: 8310 | B22: 8 Portions | C22: 1x120gm | D22: Pcs | E22: 3073780905817 | F22: 152860 | G22: =IFERROR(VLOOKUP(F22,[1]Lulu!$E:$F,2,0),"") -> 8310 | H22: =IFERROR(G22-A22,"") -> 0
A23: 302650 | B23: 24 Portions | C23: 24x360gm | D23: Ctn | E23: 3073780905831 | F23: 94649 | G23: =IFERROR(VLOOKUP(F23,[1]Lulu!$E:$F,2,0),"") -> 302650 | H23: =IFERROR(G23-A23,"") -> 0
A24: 976946 | B24: 32 Portions | C24: 1x480gm | D24: Pcs | F24: 133208 | G24: =IFERROR(VLOOKUP(F24,[1]Lulu!$E:$F,2,0),"") -> 976946 | H24: =IFERROR(G24-A24,"") -> 0
A25: 1081171 | B25: 48 Portions | C25: 1x720gm | D25: Pcs | F25: 202753 | G25: =IFERROR(VLOOKUP(F25,[1]Lulu!$E:$F,2,0),"") -> 1081171 | H25: =IFERROR(G25-A25,"") -> 0
A26: 410607 | B26: 40 Portions | C26: 5x120gm | D26: Set | E26: 3073780959704 | F26: 155146 | G26: =IFERROR(VLOOKUP(F26,[1]Lulu!$E:$F,2,0),"") -> 410607 | H26: =IFERROR(G26-A26,"") -> 0
A27: 401780 | B27: Le Enfants Promo | C27: 3x360gm | D27: Set | E27: 3251350000265 | F27: 94654 | G27: =IFERROR(VLOOKUP(F27,[1]Lulu!$E:$F,2,0),"") -> 401780 | H27: =IFERROR(G27-A27,"") -> 0
A28: 8209 | B28: 8 Portions LVQR | C28: 40x120gm | D28: Ctn | E28: 3073786155186 | F28: 155147 | G28: =IFERROR(VLOOKUP(F28,[1]Lulu!$E:$F,2,0),"") -> 8209 | H28: =IFERROR(G28-A28,"") -> 0
A29: 8214 | B29: 16 Portions | C29: 32x240gm | D29: Ctn | E29: 3073780574242 | F29: 94659 | G29: =IFERROR(VLOOKUP(F29,[1]Lulu!$E:$F,2,0),"") -> 8214 | H29: =IFERROR(G29-A29,"") -> 0
A30: 8216 | B30: 24 Portions | C30: 24x360gm | D30: Ctn | E30: 3073780574310 | F30: 94661 | G30: =IFERROR(VLOOKUP(F30,[1]Lulu!$E:$F,2,0),"") -> 8216 | H30: =IFERROR(G30-A30,"") -> 0
A31: 8218 | B31: 32 Portions | C31: 16x480gm | D31: Ctn | E31: 3073780593083 | F31: 94664 | G31: =IFERROR(VLOOKUP(F31,[1]Lulu!$E:$F,2,0),"") -> 8218 | H31: =IFERROR(G31-A31,"") -> 0
A32: 981192 | B32: 48 Portions | C32: 1X 720gm | D32: Pcs | F32: 268317 | G32: =IFERROR(VLOOKUP(F32,[1]Lulu!$E:$F,2,0),"") -> 981192 | H32: =IFERROR(G32-A32,"") -> 0
A33: 8211 | B33: 8 Portions -Light Cheese | C33: 48x120gm | D33: Ctn | E33: 3073780689014 | F33: 94656 | G33: =IFERROR(VLOOKUP(F33,[1]Lulu!$E:$F,2,0),"") -> 8211 | H33: =IFERROR(G33-A33,"") -> 0
A34: 8316 | B34: LVQ DIPPERS | C34: 1X 140gm | D34: Pcs | E34: 30737808110661 | F34: 194963 | G34: =IFERROR(VLOOKUP(F34,[1]Lulu!$E:$F,2,0),"") -> 8316 | H34: =IFERROR(G34-A34,"") -> 0
A35: 763478 | B35: LVQ DIPPERS (solo) | C35: 1x35gm | D35: Pcs | E35: 30087798 | F35: 309827 | G35: =IFERROR(VLOOKUP(F35,[1]Lulu!$E:$F,2,0),"") -> 763478 | H35: =IFERROR(G35-A35,"") -> 0
A36: 504157 | B36: LVQ 2x32p - 15% off | C36: 2x480gm | D36: Set | F36: 125019 | G36: =IFERROR(VLOOKUP(F36,[1]Lulu!$E:$F,2,0),"") -> 504157 | H36: =IFERROR(G36-A36,"") -> 0
A37: 572786 | B37: Slices Burger | C37: 32x200gm | D37: Ctn | E37: 3073780985581 | F37: 94674 | G37: =IFERROR(VLOOKUP(F37,[1]Lulu!$E:$F,2,0),"") -> 572786 | H37: =IFERROR(G37-A37,"") -> 0
A38: 574190 | B38: Slices Cheddar | C38: 32x200gm | D38: Ctn | E38: 3073780450461 | F38: 94671 | G38: =IFERROR(VLOOKUP(F38,[1]Lulu!$E:$F,2,0),"") -> 574190 | H38: =IFERROR(G38-A38,"") -> 0
A39: 572784 | B39: Slices Sandwich | C39: 32x200gm | D39: Ctn | E39: 3073780450386 | F39: 94698 | G39: =IFERROR(VLOOKUP(F39,[1]Lulu!$E:$F,2,0),"") -> 572784 | H39: =IFERROR(G39-A39,"") -> 0
A40: 574119 | B40: Slices Light | C40: 32x200gm | D40: Ctn | E40: 3073780543989 | F40: 94693 | G40: =IFERROR(VLOOKUP(F40,[1]Lulu!$E:$F,2,0),"") -> 574119 | H40: =IFERROR(G40-A40,"") -> 0
...

Sheet Sheet2
A1: LULU CODE | B1: PRODUCT | C1: PACKING | D1: ORDER | E1: BARCODES | F1: KR CODE | G1: KR CODE | H1: REMARKS
F2: =IFERROR(VLOOKUP(A2,Lulu!A:F,6,0),"") | G2: =IFERROR(VLOOKUP(E2,Lulu!E:F,2,0),"") | H2: 60126982 | I2: lulu al ansab | K2: 183 KEMIL
H3: 60132102 | I3: LULU ZAKHER MALL
H4: 60126459 | I4: LULU AMERAT
F5: =IFERROR(VLOOKUP(A5,Lulu!A:F,6,0),"") | G5: Deepak 176 | H5: 60131290 | I5: LULU SAMADDD
G6: 174 | H6: 60008648 | I6: LULU LOGISTIC
F7: =IFERROR(VLOOKUP(A7,Lulu!A:F,6,0),"") | G7: =IFERROR(VLOOKUP(E7,Lulu!E:F,2,0),"")
F8: =IFERROR(VLOOKUP(A8,Lulu!A:F,6,0),"") | G8: =IFERROR(VLOOKUP(E8,Lulu!E:F,2,0),"")
F9: =IFERROR(VLOOKUP(A9,Lulu!A:F,6,0),"") | G9: =IFERROR(VLOOKUP(E9,Lulu!E:F,2,0),"")
F10: =IFERROR(VLOOKUP(A10,Lulu!A:F,6,0),"") | G10: =IFERROR(VLOOKUP(E10,Lulu!E:F,2,0),"")
F11: =IFERROR(VLOOKUP(A11,Lulu!A:F,6,0),"") | G11: =IFERROR(VLOOKUP(E11,Lulu!E:F,2,0),"")
F12: =IFERROR(VLOOKUP(A12,Lulu!A:F,6,0),"") | G12: =IFERROR(VLOOKUP(E12,Lulu!E:F,2,0),"")
F13: =IFERROR(VLOOKUP(A13,Lulu!A:F,6,0),"") | G13: =IFERROR(VLOOKUP(E13,Lulu!E:F,2,0),"")
F14: =IFERROR(VLOOKUP(A14,Lulu!A:F,6,0),"") | G14: =IFERROR(VLOOKUP(E14,Lulu!E:F,2,0),"")
F15: =IFERROR(VLOOKUP(A15,Lulu!A:F,6,0),"") | G15: =IFERROR(VLOOKUP(E15,Lulu!E:F,2,0),"")
F16: =IFERROR(VLOOKUP(A16,Lulu!A:F,6,0),"") | G16: =IFERROR(VLOOKUP(E16,Lulu!E:F,2,0),"")
F17: =IFERROR(VLOOKUP(A17,Lulu!A:F,6,0),"") | G17: =IFERROR(VLOOKUP(E17,Lulu!E:F,2,0),"")
F18: =IFERROR(VLOOKUP(A18,Lulu!A:F,6,0),"") | G18: =IFERROR(VLOOKUP(E18,Lulu!E:F,2,0),"")
... F86: =IFERROR(VLOOKUP(A86,Lulu!A:F,6,0),"") | G86: =IFERROR(VLOOKUP(E86,Lulu!E:F,2,0),"")
A87: 99999 | F87: =IFERROR(VLOOKUP(A87,Lulu!A:F,6,0),"") | G87: =IFERROR(VLOOKUP(E87,Lulu!E:F,2,0),"")
A88: 99999 | F88: =IFERROR(VLOOKUP(A88,Lulu!A:F,6,0),"") | G88: =IFERROR(VLOOKUP(E88,Lulu!E:F,2,0),"")
A89: 99999 | F89: =IFERROR(VLOOKUP(A89,Lulu!A:F,6,0),"") | G89: =IFERROR(VLOOKUP(E89,Lulu!E:F,2,0),"")
A90: 537522 | E90: 6921211111467 | F90: =IFERROR(VLOOKUP(A90,Lulu!A:F,6,0),"") -> 395985 | G90: =IFERROR(VLOOKUP(E90,Lulu!E:F,2,0),"") -> 229187 | J90: D078
E91: 6921211112006 | F91: =IFERROR(VLOOKUP(A91,Lulu!A:F,6,0),"") | G91: =IFERROR(VLOOKUP(E91,Lulu!E:F,2,0),"") -> 229188 | J91: D078
E92: 80757450 | F92: =IFERROR(VLOOKUP(A92,Lulu!A:F,6,0),"") | G92: =IFERROR(VLOOKUP(E92,Lulu!E:F,2,0),"") -> 229190 | J92: D078
E93: 80757474 | F93: =IFERROR(VLOOKUP(A93,Lulu!A:F,6,0),"") | G93: =IFERROR(VLOOKUP(E93,Lulu!E:F,2,0),"") -> 229392 | J93: D078
E94: 80757481 | F94: =IFERROR(VLOOKUP(A94,Lulu!A:F,6,0),"") | G94: =IFERROR(VLOOKUP(E94,Lulu!E:F,2,0),"") -> 229393 | J94: D078
E95: 6291007901092 | F95: =IFERROR(VLOOKUP(A95,Lulu!A:F,6,0),"") | G95: =IFERROR(VLOOKUP(E95,Lulu!E:F,2,0),"") -> 95894 | J95: D078
E96: 8901063004016 | F96: =IFERROR(VLOOKUP(A96,Lulu!A:F,6,0),"") | G96: =IFERROR(VLOOKUP(E96,Lulu!E:F,2,0),"") -> 233419 | J96: D078
E97: 6291007915334 | F97: =IFERROR(VLOOKUP(A97,Lulu!A:F,6,0),"") | G97: =IFERROR(VLOOKUP(E97,Lulu!E:F,2,0),"") | J97: D078
E98: 6291007915341 | F98: =IFERROR(VLOOKUP(A98,Lulu!A:F,6,0),"") | G98: =IFERROR(VLOOKUP(E98,Lulu!E:F,2,0),"") | J98: D078
E99: 6291007906479 | F99: =IFERROR(VLOOKUP(A99,Lulu!A:F,6,0),"") | G99: =IFERROR(VLOOKUP(E99,Lulu!E:F,2,0),"") -> 300992
E100: 8410031122510 | F100: =IFERROR(VLOOKUP(A100,Lulu!A:F,6,0),"") | G100: =IFERROR(VLOOKUP(E100,Lulu!E:F,2,0),"") -> 176200
E101: 84196842 | F101: =IFERROR(VLOOKUP(A101,Lulu!A:F,6,0),"") | G101: =IFERROR(VLOOKUP(E101,Lulu!E:F,2,0),"") -> 176210
E102: 8992741993340 | F102: =IFERROR(VLOOKUP(A102,Lulu!A:F,6,0),"") | G102: =IFERROR(VLOOKUP(E102,Lulu!E:F,2,0),"") -> 329171
E103: 8901393020564 | F103: =IFERROR(VLOOKUP(A103,Lulu!A:F,6,0),"") | G103: =IFERROR(VLOOKUP(E103,Lulu!E:F,2,0),"") -> 324335
E104: 6925425474363 | F104: =IFERROR(VLOOKUP(A104,Lulu!A:F,6,0),"") | G104: =IFERROR(VLOOKUP(E104,Lulu!E:F,2,0),"") -> 181554
E105: 6925425474486 | F105: =IFERROR(VLOOKUP(A105,Lulu!A:F,6,0),"") | G105: =IFERROR(VLOOKUP(E105,Lulu!E:F,2,0),"") -> 181555
E106: 6291109790303 | F106: =IFERROR(VLOOKUP(A106,Lulu!A:F,6,0),"") | G106: =IFERROR(VLOOKUP(E106,Lulu!E:F,2,0),"") -> 386804
E107: 6291109790310 | F107: =IFERROR(VLOOKUP(A107,Lulu!A:F,6,0),"") | G107: =IFERROR(VLOOKUP(E107,Lulu!E:F,2,0),"") -> 386805
...

Sheet Sheet1
A1: Dear Sir,
A2: Please approve the discount for C4 Seeb against order number 6121014 for the below item:
A3: SAP CODE | B3: Product Description | C3: Packing | D3: Units per Cs | E3: Qty (in Pcs) | F3: KR Price | G3: Discount Price
A4: 3073780959704 | B4: 155146 | C4: Les Enfants 40p - (5x8p) | D4: 5 x 8 x 120gms | E4: 160 | F4: 1.567 | G4: 1.39
A5: 3073781053586 | B5: 94715 | C5: Kiri 2x24p - 10% off | D5: 2 x 8 x 432gms | E5: 120 | F5: 3.41 | G5: 2.975
A6: 3073781134193 | B6: 293732 | C6: REGAL PICON WHITE JAR 2X900G- 15% off | D6: 3x2x900gms | E6: 60 | F6: 4.705 | G6: 3.99
A7: Dear Kishore,
A8: It's a flyer order, which starts from tomorrow, so after the discount approval, please ensure delivery of the above order tomorrow.
A10: KR CODE 404560
A11: 0010 1126973 DEVON Devon Crm.Crackers 200g 3+1 0635673975043 48 EA 1.143 0.000 1.143 0.00% 0.000 54.864
A12: KR CODE 404560
A15: 70 | B15: 1126973 | C15: 404560 | D15: DEVON | E15: Devon Crm.Crackers 200g 3+1 | G15: 635673975043 | H15: 6 | I15: CAR=6EA | J15: 6.858
A17: 195536 | B17: Kiri Cheese 12P 3x200gm 3073781190922 60 EA 1EA 2.815 168.900
A19: 0040 1037891 198523 PERFETTI CH ChupaChp.Jellies Astd 3x90g PO 2020000018728 24 EA 1.014 0.000 1.014 V2 5.00% 1.217 25.553
A20: 370080
A27: 375701 | B27: BRITANNIA MARIE GOLD 80 GMS | C27: 6291007902211 | D27: 0.131 | E27: 3.144
A28: 375703 | B28: BRITANNIA VITA MARIE 122 GMS | C28: 6291007902204 | D28: 0.234 | E28: 5.616
A29: 378939 | B29: BRITANNIA WHEAT RUSK 305 GM | C29: 8901063151055 | D29: 0.575 | E29: 6.9
A33: 5 0ZZU44 365212 06291007901047
A34: Britannia Good Day
A35: Cashew Cookies, 72g
A36: 24 0.217 0.217 5.208 5.00% 0.260 5.468
A39: 678428 | B39: 138940 | C39: Mentos Gum Fresh Mint 56g | D39: 80733294 | E39: 12 | F39: CH1=6EA | G39: 5.329 | H39: @ 0.889
A40: 404577 | B40: 40087 | C40: CHUPA CHUP JELLIES- TWIN PACK 160G | D40: 1800000024803 | E40: 12 | F40: 1.35
A45: BARCODE 6291007914719 Britannia Chunkies 82g X 4 / | C45: 396374 -BRITANNIA CHUNKIES 4X82GM
A46: Britannia /
A47: 13847 | B47: NUTRO BISCUITS TASTY CRACKER 42 GMS | C47: 48X42 GM | D47: 6291007701043 | E47: 6291007700084 | F47: 95819 | G47: 401105 | H47: 401105 | I47: 401105
B49: 6291007901047 | C49: Good Day Cashew 72g | D49: 5 CTN
B50: 1003010025 | C50: 6291007901061 | D50: Britania Marie Gold 154g | E50: 5 CTN
B51: 1003010027 | C51: 6291007901085 | D51: Britania 50 50 Maska Chaska | E51: 5 CTN
B52: 1003010028 | C52: 6291007901092 | D52: Britania 50 50 | E52: 4 CTN
B53: 1003010059 | C53: 8901063136779 | D53: Britania Good Day ChocoAlm100g | E53: 5 CTN
B54: 1003010061 | C54: 8901063151017 | D54: Britania Digestive 225g | E54: 1 CTN
B55: 1003010143 | C55: 6291007905311 | D55: Britania Bourbon 200g | E55: 5 CTN
B56: 1003010168 | C56: 6291007902204 | D56: Britania Vita Marie Gold 122g | E56: 5 CTN
B57: 1003010171 | C57: 8901063165793 | D57: Britania Good Day Chunkies60g | E57: 5 CTN
A59: 14 | B59: 3073781219654/49 | C59: 301873366 | D59: Regular | E59: Les Enfants Cheese 32p - (4x8p) | I59: 16 | J59: 64 | K59: 4 | L59: 5 | M59: 1.269 | N59: 4.061 | O59: 81.216 | P59: 85.277
A60: 410295
A64: 379780
A65: 445177 3+1 | B65: 379780 | C65: Hero Baby Food Jar 125g 3+1 | D65: 1800000001835 b | E65: @ | F65: 1.368
...
