Workbook

Sheet Bel
A1: Nesto Code | B1: Packing | C1: Units per Cs | D1: Price to Trade Ro (Per Unit) | E1: Barcode (Per Unit) | F1: Product Description | G1: SAP CODE | H1: Price to Trade Ro (Cs) | I1: Barcode (Per Carton) | L1: New Price
A2: 116471 | B2: 40 x 120gms | C2: 40 | D2: 0.314 | E2: 3251350126002 | F2: Regal Picon 8 Portion | G2: 152859 | H2: 12.56 | I2: 3073781030907 | J2: =VLOOKUP(G2,[1]Sheet1!$B:$L,1,0) -> 152859 | K2: =VLOOKUP(J2,[2]Sheet1!$D:$F,3,0) -> 116471 | L2: =K2-A2 -> 0
A3: 116472 | B3: 32 x 240gms | C3: 32 | D3: 0.63 | E3: 3251350161003 | F3: Regal Picon 16 Portion | G3: 94576 | H3: 20.16 | I3: 3073780921145 | J3: =VLOOKUP(G3,[1]Sheet1!$B:$L,1,0) -> 94576 | K3: =VLOOKUP(J3,[2]Sheet1!$D:$F,3,0) -> 116472 | L3: =K3-A3 -> 0
B4: 24 x 360gms | C4: 24 | D4: 0.942 | E4: 3251350162000 | F4: Regal Picon 24 Portion | G4: 94581 | H4: 22.608 | I4: 3073780921138 | J4: =VLOOKUP(G4,[1]Sheet1!$B:$L,1,0) -> 94581 | K4: =VLOOKUP(J4,[2]Sheet1!$D:$F,3,0) -> #N/A | L4: =K4-A4 -> #N/A
A5: 116474 | B5: 16 x 480gms | C5: 16 | D5: 1.225 | E5: 3251350163007 | F5: Regal Picon 32 Portion | G5: 94590 | H5: 19.6 | I5: 3073780896559 | J5: =VLOOKUP(G5,[1]Sheet1!$B:$L,1,0) -> 94590 | K5: =VLOOKUP(J5,[2]Sheet1!$D:$F,3,0) -> 116474 | L5: =K5-A5 -> 0
B6: 8 x 720gms | C6: 8 | D6: 1.698 | E6: 3073781046601 | F6: Regal Picon 48 Portion | G6: 177009 | H6: 13.584 | I6: 3073781049848 | J6: =VLOOKUP(G6,[1]Sheet1!$B:$L,1,0) -> 177009 | K6: =VLOOKUP(J6,[2]Sheet1!$D:$F,3,0) -> #N/A | L6: =K6-A6 -> #N/A
B7: 8 x 1080gms | C7: 8 | D7: 2.08 | E7: 3073780884655 | F7: Regal Picon 72 Portion | G7: 94567 | H7: 16.64 | I7: 3073780984096 | J7: =VLOOKUP(G7,[1]Sheet1!$B:$L,1,0) -> 94567 | K7: =VLOOKUP(J7,[2]Sheet1!$D:$F,3,0) -> #N/A | L7: =K7-A7 -> #N/A
A8: 327035 | B8: 40 x 120gms | C8: 40 | D8: 0.314 | E8: 3073780905817 | F8: Les Enfants 8 Portion | G8: 152860 | H8: 12.56 | I8: 3073781030921 | J8: =VLOOKUP(G8,[1]Sheet1!$B:$L,1,0) -> 152860 | K8: =VLOOKUP(J8,[2]Sheet1!$D:$F,3,0) -> 327035 | L8: =K8-A8 -> 0
A9: 327036 | B9: 24 x 360gms | C9: 24 | D9: 0.942 | E9: 3073780905831 | F9: Les Enfants 24 Portion | G9: 94649 | H9: 22.608 | I9: 3073780905848 | J9: =VLOOKUP(G9,[1]Sheet1!$B:$L,1,0) -> 94649 | K9: =VLOOKUP(J9,[2]Sheet1!$D:$F,3,0) -> 327036 | L9: =K9-A9 -> 0
A10: 327037 | B10: 16 x 480gms | C10: 16 | D10: 1.242 | E10: 3073781021226 | F10: Les Enfants 32 Portion | G10: 133208 | H10: 19.872 | I10: 3073781021233 | J10: =VLOOKUP(G10,[1]Sheet1!$B:$L,1,0) -> 133208 | K10: =VLOOKUP(J10,[2]Sheet1!$D:$F,3,0) -> 327037 | L10: =K10-A10 -> 0
A11: 1024254 | B11: 8 x 720gms | C11: 8 | D11: 1.698 | E11: 3073781061857 | F11: Les Enfants 48 Portion | G11: 202753 | H11: 13.584 | I11: 3073781061864 | J11: =VLOOKUP(G11,[1]Sheet1!$B:$L,1,0) -> 202753 | K11: =VLOOKUP(J11,[2]Sheet1!$D:$F,3,0) -> 1024254 | L11: =K11-A11 -> 0
B12: 40 x 120gms | C12: 40 | D12: 0.404 | E12: 3073786155186 | F12: La Vache Quirit 8 Portion | G12: 155147 | H12: 16.16 | I12: 3073781030938 | J12: =VLOOKUP(G12,[1]Sheet1!$B:$L,1,0) -> 155147 | K12: =VLOOKUP(J12,[2]Sheet1!$D:$F,3,0) -> #N/A | L12: =K12-A12 -> #N/A
A13: 116567 | B13: 32 x 240gms | C13: 32 | D13: 0.751 | E13: 3073780574242 | F13: La Vache Quirit 16 Portion | G13: 94659 | H13: 24.032 | I13: 3073780961363 | J13: =VLOOKUP(G13,[1]Sheet1!$B:$L,1,0) -> 94659 | K13: =VLOOKUP(J13,[2]Sheet1!$D:$F,3,0) -> #N/A | L13: =K13-A13 -> #N/A
A14: 116568 | B14: 24 x 360gms | C14: 24 | D14: 1.098 | E14: 3073780574310 | F14: La Vache Quirit 24 Portion | G14: 94661 | H14: 26.352 | I14: 3073780795135 | J14: =VLOOKUP(G14,[1]Sheet1!$B:$L,1,0) -> 94661 | K14: =VLOOKUP(J14,[2]Sheet1!$D:$F,3,0) -> #N/A | L14: =K14-A14 -> #N/A
B15: 16 x 480gms | C15: 16 | D15: 1.444 | E15: 3073780593083 | F15: La Vache Quirit 32 Portion | G15: 94664 | H15: 23.104 | I15: 3073780830684 | J15: =VLOOKUP(G15,[1]Sheet1!$B:$L,1,0) -> 94664 | K15: =VLOOKUP(J15,[2]Sheet1!$D:$F,3,0) -> #N/A | L15: =K15-A15 -> #N/A
A16: 285448 | B16: 8 x 720gms | C16: 8 | D16: 2.114 | E16: 3073781048957 | F16: La Vache Quirit 48 Portion | G16: 268317 | H16: 16.912 | I16: 3073781061901 | J16: =VLOOKUP(G16,[1]Sheet1!$B:$L,1,0) -> 268317 | K16: =VLOOKUP(J16,[2]Sheet1!$D:$F,3,0) -> #N/A | L16: =K16-A16 -> #N/A
B17: 48 x 120gms | C17: 48 | D17: 0.462 | E17: 3073780689014 | F17: La Vache Quirit 8 Portion Light | G17: 94656 | H17: 22.176 | I17: 3073780802413 | J17: =VLOOKUP(G17,[1]Sheet1!$B:$L,1,0) -> #N/A | K17: =VLOOKUP(J17,[2]Sheet1!$D:$F,3,0) -> #N/A | L17: =K17-A17 -> #N/A
B18: 2 x 8 x 480gms | C18: 8 | D18: 2.205 | E18: 3073781053616 | F18: Regal Picon 2x32p - 10% off | G18: 94595 | H18: 17.64 | J18: =VLOOKUP(G18,[1]Sheet1!$B:$L,1,0) -> 94595 | K18: =VLOOKUP(J18,[2]Sheet1!$D:$F,3,0) -> #N/A | L18: =K18-A18 -> #N/A
A19: 327039 | B19: 5 x 8 x 120gms | C19: 8 | D19: 1.414 | E19: 3073781059793 | F19: Regal Picon 40p - (5x8p) | G19: 155145 | H19: 11.312 | J19: =VLOOKUP(G19,[1]Sheet1!$B:$L,1,0) -> 155145 | K19: =VLOOKUP(J19,[2]Sheet1!$D:$F,3,0) -> 327039 | L19: =K19-A19 -> 0
B20: 5 x 8 x 120gms | C20: 8 | D20: 1.398 | E20: 3073780959704 | F20: Les Enfants 40p - (5x8p) | G20: 155146 | H20: 11.184 | J20: =VLOOKUP(G20,[1]Sheet1!$B:$L,1,0) -> 155146 | K20: =VLOOKUP(J20,[2]Sheet1!$D:$F,3,0) -> #N/A | L20: =K20-A20 -> #N/A
B21: 5 x 8 x 120gms | C21: 8 | D21: 1.612 | E21: 3073781025194 | F21: LA VACHE QUIRIT 8P - 4P+1P FREE | G21: 139207 | H21: 12.896 | J21: =VLOOKUP(G21,[1]Sheet1!$B:$L,1,0) -> #N/A | K21: =VLOOKUP(J21,[2]Sheet1!$D:$F,3,0) -> #N/A | L21: =K21-A21 -> #N/A
B22: 2 x 8 x 480gms | C22: 8 | D22: 2.444 | E22: 3073781054521 | F22: LA VACHE QUIRIT 32 POR 2X480G @ 15% OFF | G22: 125019 | H22: 19.552 | J22: =VLOOKUP(G22,[1]Sheet1!$B:$L,1,0) -> #N/A | K22: =VLOOKUP(J22,[2]Sheet1!$D:$F,3,0) -> #N/A | L22: =K22-A22 -> #N/A
A23: 116564 | B23: 60 x 108gms | C23: 60 | D23: 0.462 | E23: 3073780839631 | F23: Kiri 6 Portion | G23: 182808 | H23: 27.72 | I23: 3073780811309 | J23: =VLOOKUP(G23,[1]Sheet1!$B:$L,1,0) -> 182808 | K23: =VLOOKUP(J23,[2]Sheet1!$D:$F,3,0) -> #N/A | L23: =K23-A23 -> #N/A
A24: 116561 | B24: 40 x 216gms | C24: 40 | D24: 0.863 | E24: 3073780624435 | F24: Kiri 12 Portion | G24: 182809 | H24: 34.52 | I24: 3073780858724 | J24: =VLOOKUP(G24,[1]Sheet1!$B:$L,1,0) -> 182809 | K24: =VLOOKUP(J24,[2]Sheet1!$D:$F,3,0) -> #N/A | L24: =K24-A24 -> #N/A
A25: 116563 | B25: 16 x 432gms | C25: 16 | D25: 1.698 | E25: 3073780767897 | F25: Kiri 24 Portion | G25: 94714 | H25: 27.168 | I25: 3073780858731 | J25: =VLOOKUP(G25,[1]Sheet1!$B:$L,1,0) -> 94714 | K25: =VLOOKUP(J25,[2]Sheet1!$D:$F,3,0) -> #N/A | L25: =K25-A25 -> #N/A
B26: 40 x 100gms | C26: 40 | D26: 0.544 | E26: 3073781141382 | F26: KIRI GREEK STYLE 6 PORTION 100G | G26: 312609 | H26: 21.76 | I26: 3073781141399 | J26: =VLOOKUP(G26,[1]Sheet1!$B:$L,1,0) -> 312609 | K26: =VLOOKUP(J26,[2]Sheet1!$D:$F,3,0) -> #N/A | L26: =K26-A26 -> #N/A
A27: 1060455 | B27: 16 x 400gms | C27: 16 | D27: 1.95 | E27: 3073781141368 | F27: KIRI GREEK STYLE 24 PORTION 400G | G27: 312610 | H27: 31.2 | I27: 3073781141375 | J27: =VLOOKUP(G27,[1]Sheet1!$B:$L,1,0) -> 312610 | K27: =VLOOKUP(J27,[2]Sheet1!$D:$F,3,0) -> 1060455 | L27: =K27-A27 -> 0
B28: 5 x 12 x 108gms | C28: 12 | D28: 1.964 | E28: 3073781053555 | F28: Kiri 5x6p - 15% off | G28: 195540 | H28: 23.568 | I28: N/A | J28: =VLOOKUP(G28,[1]Sheet1!$B:$L,1,0) -> 195540 | K28: =VLOOKUP(J28,[2]Sheet1!$D:$F,3,0) -> #N/A | L28: =K28-A28 -> #N/A
B29: 2 x 8 x 432gms | C29: 8 | D29: 3.058 | E29: 3073781053586 | F29: Kiri 2x24p - 10% off | G29: 94715 | H29: 24.464 | I29: N/A | J29: =VLOOKUP(G29,[1]Sheet1!$B:$L,1,0) -> 94715 | K29: =VLOOKUP(J29,[2]Sheet1!$D:$F,3,0) -> #N/A | L29: =K29-A29 -> #N/A
B30: 3 x 12 x 216gms | C30: 12 | D30: 2.2 | E30: 3073781053562 | F30: Kiri 3x12p - 15% off | G30: 195536 | H30: 26.4 | I30: N/A | J30: =VLOOKUP(G30,[1]Sheet1!$B:$L,1,0) -> 195536 | K30: =VLOOKUP(J30,[2]Sheet1!$D:$F,3,0) -> #N/A | L30: =K30-A30 -> #N/A
A31: 198856 | B31: 24 x 200gms | C31: 24 | D31: 0.676 | E31: 3073780998338 | F31: Regal Picon Slice Cheddar 200g | G31: 114598 | H31: 16.224 | I31: 3073780998345 | J31: =VLOOKUP(G31,[1]Sheet1!$B:$L,1,0) -> 114598 | K31: =VLOOKUP(J31,[2]Sheet1!$D:$F,3,0) -> 198856 | L31: =K31-A31 -> 0
B32: 24 x 200gms | C32: 24 | D32: 0.676 | E32: 3073780998352 | F32: Regal Picon Slice Burger 200g | G32: 114599 | H32: 16.224 | I32: 3073780998369 | J32: =VLOOKUP(G32,[1]Sheet1!$B:$L,1,0) -> 114599 | K32: =VLOOKUP(J32,[2]Sheet1!$D:$F,3,0) -> #N/A | L32: =K32-A32 -> #N/A
A33: 327038 | B33: 16 x 400gms | C33: 16 | D33: 1.352 | E33: 3073780998376 | F33: Regal Picon Slice Cheddar Family 400g | G33: 114600 | H33: 21.632 | I33: 3073780998383 | J33: =VLOOKUP(G33,[1]Sheet1!$B:$L,1,0) -> 114600 | K33: =VLOOKUP(J33,[2]Sheet1!$D:$F,3,0) -> 327038 | L33: =K33-A33 -> 0
B34: 32 x 200gms | C34: 32 | D34: 0.664 | E34: 3073780450461 | F34: La Vache Quirit Slice Cheddar 200g | G34: 94671 | H34: 21.248 | I34: 3073780985628 | J34: =VLOOKUP(G34,[1]Sheet1!$B:$L,1,0) -> 94671 | K34: =VLOOKUP(J34,[2]Sheet1!$D:$F,3,0) -> #N/A | L34: =K34-A34 -> #N/A
A35: 116557 | B35: 32 x 200gms | C35: 32 | D35: 0.664 | E35: 3073780985581 | F35: La Vache Quirit Slice Burger 200g | G35: 94674 | H35: 21.248 | I35: 3073780985598 | J35: =VLOOKUP(G35,[1]Sheet1!$B:$L,1,0) -> 94674 | K35: =VLOOKUP(J35,[2]Sheet1!$D:$F,3,0) -> 116557 | L35: =K35-A35 -> 0
B36: 32 x 200gms | C36: 32 | D36: 0.664 | E36: 3073780450386 | F36: La Vache Quirit Slice Sandwich 200g | G36: 94698 | H36: 21.248 | I36: 3073780985635 | J36: =VLOOKUP(G36,[1]Sheet1!$B:$L,1,0) -> 94698 | K36: =VLOOKUP(J36,[2]Sheet1!$D:$F,3,0) -> #N/A | L36: =K36-A36 -> #N/A
A37: 116572 | B37: 32 x 200gms | C37: 32 | D37: 0.664 | E37: 3073780543989 | F37: La Vache Quirit Slice Light 200g | G37: 94693 | H37: 21.248 | I37: 3073780985642 | J37: =VLOOKUP(G37,[1]Sheet1!$B:$L,1,0) -> 94693 | K37: =VLOOKUP(J37,[2]Sheet1!$D:$F,3,0) -> #N/A | L37: =K37-A37 -> #N/A
A38: 198856 | B38: 12 x 480gms | C38: 12 | D38: 1.473 | E38: 3073780985604 | F38: La Vache Quirit Slice Cheddar Family 480g | G38: 94672 | H38: 17.676 | I38: 3073780985611 | J38: =VLOOKUP(G38,[1]Sheet1!$B:$L,1,0) -> 94672 | K38: =VLOOKUP(J38,[2]Sheet1!$D:$F,3,0) -> #N/A | L38: =K38-A38 -> #N/A
B39: 12 x 480gms | C39: 12 | D39: 1.473 | E39: 3073780999816 | F39: La Vache Quirit Slice Light Family 480g | G39: 318173 | H39: 17.676 | I39: 3073780999823 | J39: =VLOOKUP(G39,[1]Sheet1!$B:$L,1,0) -> 318173 | K39: =VLOOKUP(J39,[2]Sheet1!$D:$F,3,0) -> #N/A | L39: =K39-A39 -> #N/A
A40: 1060456 | B40: 18 x 200gms | C40: 18 | D40: 0.825 | E40: 3073781141429 | F40: KIRI GREEK TUB 200G (X18) | G40: 312611 | H40: 14.85 | I40: 3073781141436 | J40: =VLOOKUP(G40,[1]Sheet1!$B:$L,1,0) -> 312611 | K40: =VLOOKUP(J40,[2]Sheet1!$D:$F,3,0) -> 1060456 | L40: =K40-A40 -> 0
...

Sheet Sheet2
A1: Nesto Code | B1: Product Description | C1: SAP CODE | D1: Barcode (Per Unit) | E1: SAP CODE | F1: Product Description
B2: =IFERROR(VLOOKUP(A2,Bel!A:F,6,0),"") | C2: =IFERROR(VLOOKUP($A2,Bel!$A:$G,7,0),"") | E2: =IFERROR(VLOOKUP(D2,Bel!$E:$G,3,0),"")
B3: =IFERROR(VLOOKUP(A3,Bel!A:F,6,0),"") | C3: =IFERROR(VLOOKUP(A3,Bel!A:G,7,0),"") | D3: 3073786155186 | E3: =IFERROR(VLOOKUP(D3,Bel!$E:$G,3,0),"") -> 155147
B4: =IFERROR(VLOOKUP(A4,Bel!A:F,6,0),"") | C4: =IFERROR(VLOOKUP(A4,Bel!A:G,7,0),"") | D4: 3073781010749 | E4: =IFERROR(VLOOKUP(D4,Bel!$E:$G,3,0),"") -> 293032
B5: =IFERROR(VLOOKUP(A5,Bel!A:F,6,0),"") | C5: =IFERROR(VLOOKUP(A5,Bel!A:G,7,0),"") | E5: =IFERROR(VLOOKUP(D5,Bel!$E:$G,3,0),"")
B6: =IFERROR(VLOOKUP(A6,Bel!A:F,6,0),"") | C6: =IFERROR(VLOOKUP(A6,Bel!A:G,7,0),"") | E6: =IFERROR(VLOOKUP(D6,Bel!$E:$G,3,0),"")
B7: =IFERROR(VLOOKUP(A7,Bel!A:F,6,0),"") | C7: =IFERROR(VLOOKUP(A7,Bel!A:G,7,0),"") | E7: =IFERROR(VLOOKUP(D7,Bel!$E:$G,3,0),"")
B8: =IFERROR(VLOOKUP(A8,Bel!A:F,6,0),"") | C8: =IFERROR(VLOOKUP(A8,Bel!A:G,7,0),"") | E8: =IFERROR(VLOOKUP(D8,Bel!$E:$G,3,0),"")
B9: =IFERROR(VLOOKUP(A9,Bel!A:F,6,0),"") | C9: =IFERROR(VLOOKUP(A9,Bel!A:G,7,0),"") | E9: =IFERROR(VLOOKUP(D9,Bel!$E:$G,3,0),"")
B10: =IFERROR(VLOOKUP(A10,Bel!A:F,6,0),"") | C10: =IFERROR(VLOOKUP(A10,Bel!A:G,7,0),"") | E10: =IFERROR(VLOOKUP(D10,Bel!$E:$G,3,0),"")
B11: =IFERROR(VLOOKUP(A11,Bel!A:F,6,0),"") | C11: =IFERROR(VLOOKUP(A11,Bel!A:G,7,0),"") | E11: =IFERROR(VLOOKUP(D11,Bel!$E:$G,3,0),"")
B12: =IFERROR(VLOOKUP(A12,Bel!A:F,6,0),"") | C12: =IFERROR(VLOOKUP(A12,Bel!A:G,7,0),"") | E12: =IFERROR(VLOOKUP(D12,Bel!$E:$G,3,0),"")
B13: =IFERROR(VLOOKUP(A13,Bel!A:F,6,0),"") | C13: =IFERROR(VLOOKUP(A13,Bel!A:G,7,0),"") | E13: =IFERROR(VLOOKUP(D13,Bel!$E:$G,3,0),"")
B14: =IFERROR(VLOOKUP(A14,Bel!A:F,6,0),"") | C14: =IFERROR(VLOOKUP(A14,Bel!A:G,7,0),"") | E14: =IFERROR(VLOOKUP(D14,Bel!$E:$G,3,0),"")
B15: =IFERROR(VLOOKUP(A15,Bel!A:F,6,0),"") | C15: =IFERROR(VLOOKUP(A15,Bel!A:G,7,0),"") | E15: =IFERROR(VLOOKUP(D15,Bel!$E:$G,3,0),"")
B16: =IFERROR(VLOOKUP(A16,Bel!A:F,6,0),"") | C16: =IFERROR(VLOOKUP(A16,Bel!A:G,7,0),"") | E16: =IFERROR(VLOOKUP(D16,Bel!$E:$G,3,0),"")
... B55: =IFERROR(VLOOKUP(A55,Bel!A:F,6,0),"") | C55: =IFERROR(VLOOKUP(A55,Bel!A:G,7,0),"") | E55: =IFERROR(VLOOKUP(D55,Bel!$E:$G,3,0),"")
B56: =IFERROR(VLOOKUP(A56,Bel!A:F,6,0),"") | C56: =IFERROR(VLOOKUP(A56,Bel!A:G,7,0),"") | E56: =IFERROR(VLOOKUP(D54,Bel!$E:$G,3,0),"")
B57: =IFERROR(VLOOKUP(A57,Bel!A:F,6,0),"") | C57: =IFERROR(VLOOKUP(A57,Bel!A:G,7,0),"") | E57: =IFERROR(VLOOKUP(D55,Bel!$E:$G,3,0),"")
B58: =IFERROR(VLOOKUP(A58,Bel!A:F,6,0),"") | C58: =IFERROR(VLOOKUP(A58,Bel!A:G,7,0),"") | E58: =IFERROR(VLOOKUP(D56,Bel!$E:$G,3,0),"")
B59: =IFERROR(VLOOKUP(A59,Bel!A:F,6,0),"") | C59: =IFERROR(VLOOKUP(A59,Bel!A:G,7,0),"") | E59: =IFERROR(VLOOKUP(D57,Bel!$E:$G,3,0),"")
B60: =IFERROR(VLOOKUP(A60,Bel!A:F,6,0),"") | C60: =IFERROR(VLOOKUP(A60,Bel!A:G,7,0),"") | E60: =IFERROR(VLOOKUP(D58,Bel!$E:$G,3,0),"")
B61: =IFERROR(VLOOKUP(A61,Bel!A:F,6,0),"") | C61: =IFERROR(VLOOKUP(A61,Bel!A:G,7,0),"") | E61: =IFERROR(VLOOKUP(D59,Bel!$E:$G,3,0),"")
B62: =IFERROR(VLOOKUP(A62,Bel!A:F,6,0),"") | C62: =IFERROR(VLOOKUP(A62,Bel!A:G,7,0),"") | E62: =IFERROR(VLOOKUP(D60,Bel!$E:$G,3,0),"")
B63: =IFERROR(VLOOKUP(A63,Bel!A:F,6,0),"") | C63: =IFERROR(VLOOKUP(A63,Bel!A:G,7,0),"") | E63: =IFERROR(VLOOKUP(D61,Bel!$E:$G,3,0),"")
B64: =IFERROR(VLOOKUP(A64,Bel!A:F,6,0),"") | C64: =IFERROR(VLOOKUP(A64,Bel!A:G,7,0),"") | E64: =IFERROR(VLOOKUP(D62,Bel!$E:$G,3,0),"")
B65: =IFERROR(VLOOKUP(A65,Bel!A:F,6,0),"") | C65: =IFERROR(VLOOKUP(A65,Bel!A:G,7,0),"") | E65: =IFERROR(VLOOKUP(D63,Bel!$E:$G,3,0),"")
B66: =IFERROR(VLOOKUP(A66,Bel!A:F,6,0),"") | C66: =IFERROR(VLOOKUP(A66,Bel!A:G,7,0),"") | E66: =IFERROR(VLOOKUP(D64,Bel!$E:$G,3,0),"")
B67: =IFERROR(VLOOKUP(A67,Bel!A:F,6,0),"") | C67: =IFERROR(VLOOKUP(A67,Bel!A:G,7,0),"") | E67: =IFERROR(VLOOKUP(D65,Bel!$E:$G,3,0),"")
... B71: =IFERROR(VLOOKUP(A71,Bel!A:F,6,0),"") | C71: =IFERROR(VLOOKUP(A71,Bel!A:G,7,0),"") | E71: =IFERROR(VLOOKUP(D69,Bel!$E:$G,3,0),"")
B72: =IFERROR(VLOOKUP(A72,Bel!A:F,6,0),"") | C72: =IFERROR(VLOOKUP(A72,Bel!A:G,7,0),"") | E72: =IFERROR(VLOOKUP(D72,Bel!$E:$G,3,0),"")
B73: =IFERROR(VLOOKUP(A73,Bel!A:F,6,0),"") | C73: =IFERROR(VLOOKUP(A73,Bel!A:G,7,0),"") | E73: =IFERROR(VLOOKUP(D73,Bel!$E:$G,3,0),"")
B74: =IFERROR(VLOOKUP(A74,Bel!A:F,6,0),"") | C74: =IFERROR(VLOOKUP(A74,Bel!A:G,7,0),"") | E74: =IFERROR(VLOOKUP(D74,Bel!$E:$G,3,0),"")
B75: =IFERROR(VLOOKUP(A75,Bel!A:F,6,0),"") | C75: =IFERROR(VLOOKUP(A75,Bel!A:G,7,0),"") | E75: =IFERROR(VLOOKUP(D75,Bel!$E:$G,3,0),"")
B76: =IFERROR(VLOOKUP(A76,Bel!A:F,6,0),"") | C76: =IFERROR(VLOOKUP(A76,Bel!A:G,7,0),"") | E76: =IFERROR(VLOOKUP(D76,Bel!$E:$G,3,0),"")
B77: =IFERROR(VLOOKUP(A77,Bel!A:F,6,0),"") | C77: =IFERROR(VLOOKUP(A77,Bel!A:G,7,0),"") | E77: =IFERROR(VLOOKUP(D77,Bel!$E:$G,3,0),"")
B78: =IFERROR(VLOOKUP(A78,Bel!A:F,6,0),"") | C78: =IFERROR(VLOOKUP(A78,Bel!A:G,7,0),"") | E78: =IFERROR(VLOOKUP(D78,Bel!$E:$G,3,0),"")
B79: =IFERROR(VLOOKUP(A79,Bel!A:F,6,0),"") | C79: =IFERROR(VLOOKUP(A79,Bel!A:G,7,0),"") | E79: =IFERROR(VLOOKUP(D79,Bel!$E:$G,3,0),"")
B80: =IFERROR(VLOOKUP(A80,Bel!A:F,6,0),"") | C80: =IFERROR(VLOOKUP(A80,Bel!A:G,7,0),"") | E80: =IFERROR(VLOOKUP(D80,Bel!$E:$G,3,0),"")
B81: =IFERROR(VLOOKUP(A81,Bel!A:F,6,0),"") | C81: =IFERROR(VLOOKUP(A81,Bel!A:G,7,0),"") | E81: =IFERROR(VLOOKUP(D81,Bel!$E:$G,3,0),"")
...
